<?xml version="1.0" encoding="utf-8"?>
<!-- This URDF was automatically created by SolidWorks to URDF Exporter! Originally created by Stephen Brawner (brawner@gmail.com) 
     Commit Version: 1.5.1-0-g916b5db  Build Version: 1.5.7152.31018
     For more information, please see http://wiki.ros.org/sw_urdf_exporter -->
<robot
  name="stoch3">
  <link
    name="base_link">
    <inertial>
      <origin
        xyz="6.5357E-17 -2.4175E-17 1.0657E-17"
        rpy="0 0 0" />
      <mass
        value="4.11" />
      <inertia
        ixx="0.0082534"
        ixy="-2.9089E-18"
        ixz="-1.9375E-20"
        iyy="0.01565"
        iyz="5.1387E-19"
        izz="0.020188" />
    </inertial>
    <visual>
      <origin
        xyz="0 0 0"
        rpy="0 0 0" />
      <geometry>
        <mesh
          filename="package://stoch3/meshes/base_link.STL" />
      </geometry>
      <material
        name="">
        <color
          rgba="0.79216 0.81961 0.93333 1" />
      </material>
    </visual>
    <collision>
      <origin
        xyz="0 0 0"
        rpy="0 0 0" />
      <geometry>
        <mesh
          filename="package://stoch3/meshes/base_link.STL" />
      </geometry>
    </collision>
  </link>
  <joint
    name="motor_br_upper_knee_joint"
    type="revolute">
    <origin
      xyz="-0.19231 -0.0555 -0.23026"
      rpy="0 0 0" />
    <parent
      link="motor_br_upper_hip_link" />
    <child
      link="motor_br_upper_knee_link" />
    <axis
      xyz="0 -1 0" />
    <limit
      lower="-12.566"
      upper="12.566"
      effort="30"
      velocity="100" />
  </joint>
  <link
    name="motor_front_left_abd_link">
    <inertial>
      <origin
        xyz="0.042267 0.0017672 6.4461E-09"
        rpy="0 0 0" />
      <mass
        value="1.702" />
      <inertia
        ixx="0.00063429"
        ixy="1.7836E-13"
        ixz="9.5169E-11"
        iyy="0.00063429"
        iyz="-2.0068E-08"
        izz="0.00051618" />
    </inertial>
    <visual>
      <origin
        xyz="0 0 0"
        rpy="0 0 0" />
      <geometry>
        <mesh
          filename="package://stoch3/meshes/motor_front_left_abd_link.STL" />
      </geometry>
      <material
        name="">
        <color
          rgba="0.79216 0.81961 0.93333 1" />
      </material>
    </visual>
    <collision>
      <origin
        xyz="0 0 0"
        rpy="0 0 0" />
      <geometry>
        <mesh
          filename="package://stoch3/meshes/motor_front_left_abd_link.STL" />
      </geometry>
    </collision>
  </link>
  <joint
    name="motor_front_left_abd_joint"
    type="revolute">
    <origin
      xyz="0.1715 0.075 0"
      rpy="0 0 0" />
    <parent
      link="base_link" />
    <child
      link="motor_front_left_abd_link" />
    <axis
      xyz="-1 0 0" />
    <limit
      lower="-0.34907"
      upper="3.4907"
      effort="30"
      velocity="100" />
  </joint>
  <link
    name="motor_fl_upper_hip_link">
    <inertial>
      <origin
        xyz="-0.026428 0.0081065 -0.031643"
        rpy="0 0 0" />
      <mass
        value="1.561" />
      <inertia
        ixx="0.0011269"
        ixy="-2.9331E-05"
        ixz="-0.0006139"
        iyy="0.0018192"
        iyz="-3.514E-05"
        izz="0.00090459" />
    </inertial>
    <visual>
      <origin
        xyz="0 0 0"
        rpy="0 0 0" />
      <geometry>
        <mesh
          filename="package://stoch3/meshes/motor_fl_upper_hip_link.STL" />
      </geometry>
      <material
        name="">
        <color
          rgba="0.79216 0.81961 0.93333 1" />
      </material>
    </visual>
    <collision>
      <origin
        xyz="0 0 0"
        rpy="0 0 0" />
      <geometry>
        <mesh
          filename="package://stoch3/meshes/motor_fl_upper_hip_link.STL" />
      </geometry>
    </collision>
  </link>
  <joint
    name="motor_fl_upper_hip_joint"
    type="revolute">
    <origin
      xyz="0.0845 0.0625 0"
      rpy="0 0 0" />
    <parent
      link="motor_front_left_abd_link" />
    <child
      link="motor_fl_upper_hip_link" />
    <axis
      xyz="0 -1 0" />
    <limit
      lower="-12.566"
      upper="12.566"
      effort="30"
      velocity="100" />
  </joint>
  <link
    name="motor_fl_upper_knee_link">
    <inertial>
      <origin
        xyz="0.093564 -0.0003826 -0.11724"
        rpy="0 0 0" />
      <mass
        value="0.125" />
      <inertia
        ixx="0.0019186"
        ixy="9.5355E-11"
        ixz="0.0014742"
        iyy="0.0031459"
        iyz="8.0663E-11"
        izz="0.0012478" />
    </inertial>
    <visual>
      <origin
        xyz="0 0 0"
        rpy="0 0 0" />
      <geometry>
        <mesh
          filename="package://stoch3/meshes/motor_fl_upper_knee_link.STL" />
      </geometry>
      <material
        name="">
        <color
          rgba="0.79216 0.81961 0.93333 1" />
      </material>
    </visual>
    <collision>
      <origin
        xyz="0 0 0"
        rpy="0 0 0" />
      <geometry>
        <mesh
          filename="package://stoch3/meshes/motor_fl_upper_knee_link.STL" />
      </geometry>
    </collision>
  </link>
  <joint
    name="motor_fl_upper_knee_joint"
    type="revolute">
    <origin
      xyz="-0.19231 0.0555 -0.23026"
      rpy="0 0 0" />
    <parent
      link="motor_fl_upper_hip_link" />
    <child
      link="motor_fl_upper_knee_link" />
    <axis
      xyz="0 -1 0" />
    <limit
      lower="-12.566"
      upper="12.566"
      effort="30"
      velocity="100" />
  </joint>
  <link
    name="motor_front_right_abd_link">
    <inertial>
      <origin
        xyz="0.042267 -0.0017671 -4.4384E-10"
        rpy="0 0 0" />
      <mass
        value="1.702" />
      <inertia
        ixx="0.00063429"
        ixy="5.138E-10"
        ixz="-5.8189E-11"
        iyy="0.00063429"
        iyz="-2.0068E-08"
        izz="0.00051618" />
    </inertial>
    <visual>
      <origin
        xyz="0 0 0"
        rpy="0 0 0" />
      <geometry>
        <mesh
          filename="package://stoch3/meshes/motor_front_right_abd_link.STL" />
      </geometry>
      <material
        name="">
        <color
          rgba="0.79216 0.81961 0.93333 1" />
      </material>
    </visual>
    <collision>
      <origin
        xyz="0 0 0"
        rpy="0 0 0" />
      <geometry>
        <mesh
          filename="package://stoch3/meshes/motor_front_right_abd_link.STL" />
      </geometry>
    </collision>
  </link>
  <joint
    name="motor_front_right_abd_joint"
    type="revolute">
    <origin
      xyz="0.1715 -0.075 0"
      rpy="0 0 0" />
    <parent
      link="base_link" />
    <child
      link="motor_front_right_abd_link" />
    <axis
      xyz="-1 0 0" />
    <limit
      lower="0.34907"
      upper="-3.4907"
      effort="30"
      velocity="100" />
  </joint>
  <link
    name="motor_fr_upper_hip_link">
    <inertial>
      <origin
        xyz="-0.026429 -0.0081064 -0.031643"
        rpy="0 0 0" />
      <mass
        value="1.561" />
      <inertia
        ixx="0.0011269"
        ixy="2.9354E-05"
        ixz="-0.00061391"
        iyy="0.0018192"
        iyz="3.5122E-05"
        izz="0.00090462" />
    </inertial>
    <visual>
      <origin
        xyz="0 0 0"
        rpy="0 0 0" />
      <geometry>
        <mesh
          filename="package://stoch3/meshes/motor_fr_upper_hip_link.STL" />
      </geometry>
      <material
        name="">
        <color
          rgba="0.79216 0.81961 0.93333 1" />
      </material>
    </visual>
    <collision>
      <origin
        xyz="0 0 0"
        rpy="0 0 0" />
      <geometry>
        <mesh
          filename="package://stoch3/meshes/motor_fr_upper_hip_link.STL" />
      </geometry>
    </collision>
  </link>
  <joint
    name="motor_fr_upper_hip_joint"
    type="revolute">
    <origin
      xyz="0.0845 -0.0625 0"
      rpy="0 0 0" />
    <parent
      link="motor_front_right_abd_link" />
    <child
      link="motor_fr_upper_hip_link" />
    <axis
      xyz="0 -1 0" />
    <limit
      lower="-12.566"
      upper="12.566"
      effort="30"
      velocity="100" />
  </joint>
  <link
    name="motor_fr_upper_knee_link">
    <inertial>
      <origin
        xyz="0.093565 0.0003826 -0.11724"
        rpy="0 0 0" />
      <mass
        value="0.125" />
      <inertia
        ixx="0.0019186"
        ixy="9.9804E-11"
        ixz="0.0014742"
        iyy="0.0031459"
        iyz="7.5087E-11"
        izz="0.0012478" />
    </inertial>
    <visual>
      <origin
        xyz="0 0 0"
        rpy="0 0 0" />
      <geometry>
        <mesh
          filename="package://stoch3/meshes/motor_fr_upper_knee_link.STL" />
      </geometry>
      <material
        name="">
        <color
          rgba="0.79216 0.81961 0.93333 1" />
      </material>
    </visual>
    <collision>
      <origin
        xyz="0 0 0"
        rpy="0 0 0" />
      <geometry>
        <mesh
          filename="package://stoch3/meshes/motor_fr_upper_knee_link.STL" />
      </geometry>
    </collision>
  </link>
  <joint
    name="motor_fr_upper_knee_joint"
    type="revolute">
    <origin
      xyz="-0.19231 -0.0555 -0.23026"
      rpy="0 0 0" />
    <parent
      link="motor_fr_upper_hip_link" />
    <child
      link="motor_fr_upper_knee_link" />
    <axis
      xyz="0 -1 0" />
    <limit
      lower="-12.566"
      upper="12.566"
      effort="30"
      velocity="100" />
  </joint>
  <link
    name="motor_back_left_abd_link">
    <inertial>
      <origin
        xyz="-0.042267 0.0017671 4.4356E-10"
        rpy="0 0 0" />
      <mass
        value="1.702" />
      <inertia
        ixx="0.00063429"
        ixy="5.1342E-10"
        ixz="5.3528E-11"
        iyy="0.00063429"
        iyz="-1.9957E-08"
        izz="0.00051618" />
    </inertial>
    <visual>
      <origin
        xyz="0 0 0"
        rpy="0 0 0" />
      <geometry>
        <mesh
          filename="package://stoch3/meshes/motor_back_left_abd_link.STL" />
      </geometry>
      <material
        name="">
        <color
          rgba="0.79216 0.81961 0.93333 1" />
      </material>
    </visual>
    <collision>
      <origin
        xyz="0 0 0"
        rpy="0 0 0" />
      <geometry>
        <mesh
          filename="package://stoch3/meshes/motor_back_left_abd_link.STL" />
      </geometry>
    </collision>
  </link>
  <joint
    name="motor_back_left_abd_joint"
    type="revolute">
    <origin
      xyz="-0.1715 0.075 0"
      rpy="0 0 0" />
    <parent
      link="base_link" />
    <child
      link="motor_back_left_abd_link" />
    <axis
      xyz="1 0 0" />
    <limit
      lower="-0.34907"
      upper="3.4907"
      effort="30"
      velocity="100" />
  </joint>
  <link
    name="motor_bl_upper_hip_link">
    <inertial>
      <origin
        xyz="-0.026428 0.0081065 -0.031643"
        rpy="0 0 0" />
      <mass
        value="1.561" />
      <inertia
        ixx="0.0011269"
        ixy="-2.9331E-05"
        ixz="-0.0006139"
        iyy="0.0018192"
        iyz="-3.514E-05"
        izz="0.00090459" />
    </inertial>
    <visual>
      <origin
        xyz="0 0 0"
        rpy="0 0 0" />
      <geometry>
        <mesh
          filename="package://stoch3/meshes/motor_bl_upper_hip_link.STL" />
      </geometry>
      <material
        name="">
        <color
          rgba="0.79216 0.81961 0.93333 1" />
      </material>
    </visual>
    <collision>
      <origin
        xyz="0 0 0"
        rpy="0 0 0" />
      <geometry>
        <mesh
          filename="package://stoch3/meshes/motor_bl_upper_hip_link.STL" />
      </geometry>
    </collision>
  </link>
  <joint
    name="motor_bl_upper_hip_joint"
    type="revolute">
    <origin
      xyz="-0.0845000000000005 0.062500000000128 0"
      rpy="0 0 0" />
    <parent
      link="motor_back_left_abd_link" />
    <child
      link="motor_bl_upper_hip_link" />
    <axis
      xyz="0 -1 0" />
    <limit
      lower="-12.566"
      upper="12.566"
      effort="30"
      velocity="100" />
  </joint>
  <link
    name="motor_bl_upper_knee_link">
    <inertial>
      <origin
        xyz="0.093564 -0.0003826 -0.11724"
        rpy="0 0 0" />
      <mass
        value="0.125" />
      <inertia
        ixx="0.0019186"
        ixy="9.5355E-11"
        ixz="0.0014742"
        iyy="0.0031459"
        iyz="8.0663E-11"
        izz="0.0012478" />
    </inertial>
    <visual>
      <origin
        xyz="0 0 0"
        rpy="0 0 0" />
      <geometry>
        <mesh
          filename="package://stoch3/meshes/motor_bl_upper_knee_link.STL" />
      </geometry>
      <material
        name="">
        <color
          rgba="0.79216 0.81961 0.93333 1" />
      </material>
    </visual>
    <collision>
      <origin
        xyz="0 0 0"
        rpy="0 0 0" />
      <geometry>
        <mesh
          filename="package://stoch3/meshes/motor_bl_upper_knee_link.STL" />
      </geometry>
    </collision>
  </link>
  <joint
    name="motor_bl_upper_knee_joint"
    type="revolute">
    <origin
      xyz="-0.19231 0.0555 -0.23026"
      rpy="0 0 0" />
    <parent
      link="motor_bl_upper_hip_link" />
    <child
      link="motor_bl_upper_knee_link" />
    <axis
      xyz="0 -1 0" />
    <limit
      lower="-12.566"
      upper="12.566"
      effort="30"
      velocity="100" />
  </joint>
  <link
    name="motor_back_right_abd_link">
    <inertial>
      <origin
        xyz="6.5357E-17 -2.4175E-17 1.0657E-17"
        rpy="0 0 0" />
      <mass
        value="4.11" />
      <inertia
        ixx="0.0082534"
        ixy="-2.9089E-18"
        ixz="-1.9375E-20"
        iyy="0.01565"
        iyz="5.1387E-19"
        izz="0.020188" />
    </inertial>
    <visual>
      <origin
        xyz="0 0 0"
        rpy="0 0 0" />
      <geometry>
        <mesh
          filename="package://stoch3/meshes/motor_back_right_abd_link.STL" />
      </geometry>
      <material
        name="">
        <color
          rgba="0.79216 0.81961 0.93333 1" />
      </material>
    </visual>
    <collision>
      <origin
        xyz="0 0 0"
        rpy="0 0 0" />
      <geometry>
        <mesh
          filename="package://stoch3/meshes/motor_back_right_abd_link.STL" />
      </geometry>
    </collision>
  </link>
  <joint
    name="motor_back_right_abd_joint"
    type="revolute">
    <origin
      xyz="-0.1715 -0.075 0"
      rpy="0 0 0" />
    <parent
      link="base_link" />
    <child
      link="motor_back_right_abd_link" />
    <axis
      xyz="1 0 0" />
    <limit
      lower="0.34907"
      upper="-3.4907"
      effort="30"
      velocity="100" />
  </joint>
  <link
    name="motor_br_upper_hip_link">
    <inertial>
      <origin
        xyz="-0.026429 -0.0081064 -0.031643"
        rpy="0 0 0" />
      <mass
        value="1.561" />
      <inertia
        ixx="0.0011269"
        ixy="2.9354E-05"
        ixz="-0.00061391"
        iyy="0.0018192"
        iyz="3.5122E-05"
        izz="0.00090462" />
    </inertial>
    <visual>
      <origin
        xyz="0 0 0"
        rpy="0 0 0" />
      <geometry>
        <mesh
          filename="package://stoch3/meshes/motor_br_upper_hip_link.STL" />
      </geometry>
      <material
        name="">
        <color
          rgba="0.79216 0.81961 0.93333 1" />
      </material>
    </visual>
    <collision>
      <origin
        xyz="0 0 0"
        rpy="0 0 0" />
      <geometry>
        <mesh
          filename="package://stoch3/meshes/motor_br_upper_hip_link.STL" />
      </geometry>
    </collision>
  </link>
  <joint
    name="motor_br_upper_hip_joint"
    type="revolute">
    <origin
      xyz="-0.0845 -0.0625 0"
      rpy="0 0 0" />
    <parent
      link="motor_back_right_abd_link" />
    <child
      link="motor_br_upper_hip_link" />
    <axis
      xyz="0 -1 0" />
    <limit
      lower="-12.566"
      upper="12.566"
      effort="30"
      velocity="100" />
  </joint>
  <link
    name="motor_br_upper_knee_link">
    <inertial>
      <origin
        xyz="0.093565 0.0003826 -0.11724"
        rpy="0 0 0" />
      <mass
        value="0.125" />
      <inertia
        ixx="0.0019186"
        ixy="9.9804E-11"
        ixz="0.0014742"
        iyy="0.0031459"
        iyz="7.5087E-11"
        izz="0.0012478" />
    </inertial>
    <visual>
      <origin
        xyz="0 0 0"
        rpy="0 0 0" />
      <geometry>
        <mesh
          filename="package://stoch3/meshes/motor_br_upper_knee_link.STL" />
      </geometry>
      <material
        name="">
        <color
          rgba="0.79216 0.81961 0.93333 1" />
      </material>
    </visual>
    <collision>
      <origin
        xyz="0 0 0"
        rpy="0 0 0" />
      <geometry>
        <mesh
          filename="package://stoch3/meshes/motor_br_upper_knee_link.STL" />
      </geometry>
    </collision>
  </link>
  <joint
    name="motor_br_upper_knee_joint"
    type="revolute">
    <origin
      xyz="-0.19231 -0.0555 -0.23026"
      rpy="0 0 0" />
    <parent
      link="motor_br_upper_hip_link" />
    <child
      link="motor_br_upper_knee_link" />
    <axis
      xyz="0 -1 0" />
    <limit
      lower="-12.566"
      upper="12.566"
      effort="30"
      velocity="100" />
  </joint>
</robot>